
function test_manual_throw() {
    try {
        log("test_manual_throw(): before throw");
        throw "manually thrown error";
        log("test_manual_throw(): after throw");
    } catch (e) {
        log("test_manual_throw(): in catch block, exception=" + str(e));
    } finally {
        log("test_manual_throw(): in finally block");
    }
}

function test_division(divisor) {
    try {
        log("test_division(" + str(divisor) + "): before division");
        a = 1 / divisor;
        log("test_division(" + str(divisor) + "): after division");
    } catch (e) {
        log("test_division(" + str(divisor) + "): in catch block, exception=" + str(e));
    } finally {
        log("test_division(" + str(divisor) + "): in finally block");
    }
}

function risky_operation() {
    try {
        log("risky_operation(): attempting risky operation");
        throw "that did not go well!";
        log("risky_operation(): risky operation succeeded ???");
    } finally {
        log("risky_operation(): in finally clause");
    }
}

function test_nested_exceptions() {
    try {
        log("test_nested_exceptions(): before risky_operation()");
        risky_operation();
        log("test_nested_exceptions(): after risky_operation()");
    } catch (e) {
        log("test_nested_exceptions(): risky_operation() excepted: " + str(e));
        throw "aaaa!";
    } finally {
        log("test_nested_exceptions(): cleaning up...");
        throw "outer-finally-block is throwing!";
    }
}

test_manual_throw();
test_division(1);
test_division(0);
test_nested_exceptions();
